Workbook
Name NativeTimeline_Order_Date: #N/A
Name Slicer_Order_Status: #N/A
Name Slicer_Product_Category1: #N/A
Name Slicer_Region: #N/A

Sheet Dashboard
A1: E-Commerce Sales Analytics

Sheet sales_data_original
A1: Order_ID | B1: Order_Date | C1: Customer_Name | D1: Customer_Email | E1: Region | F1: City | G1: Product_Category | H1: Product_Name | I1: Quantity | J1: Unit_Price | K1: Discount_Percent | L1: Shipping_Cost | M1: Payment_Method | N1: Order_Status
A2: ORD-1001 | B2: 45296 | C2: John Smith | D2: john.smith@email.com | E2: North | F2: New York | G2: Electronics | H2: Wireless Mouse | I2: 2 | J2: 29.99 | K2: 10 | L2: 5.99 | M2: Credit Card | N2: Delivered
A3: ORD-1002 | B3: 45298 | C3: Sarah Johnson | D3: sarah.j@email.com | E3: South | F3: Miami | G3: Home & Garden | H3: Plant Pot Set | I3: 1 | J3: 45.5 | K3: 0 | L3: 7.5 | M3: PayPal | N3: Delivered
A4: ORD-1003 | B4: 45299 | C4: Michael Brown | D4: m.brown@email.com | E4: East | F4: Boston | G4: Electronics | H4: USB Cable | I4: 5 | J4: 12.99 | K4: 15 | L4: 4.99 | M4: Credit Card | N4: Delivered
A5: ORD-1004 | B5: 45301 | C5: Emily Davis | D5: emily.d@email.com | E5: West | F5: Los Angeles | G5: Clothing | H5: Cotton T-Shirt | I5: 3 | J5: 19.99 | K5: 20 | L5: 6.5 | M5: Debit Card | N5: Delivered
A6: ORD-1005 | B6: 45303 | C6: David Wilson | D6: d.wilson@email.com | E6: North | F6: Chicago | G6: Electronics | H6: Keyboard | I6: 1 | J6: 89.99 | K6: 5 | L6: 8.99 | M6: Credit Card | N6: Delivered
A7: ORD-1006 | B7: 45306 | C7: Lisa Anderson | D7: lisa.a@email.com | E7: South | F7: Houston | G7: Home & Garden | H7: Garden Tools | I7: 2 | J7: 34.99 | K7: 0 | L7: 9.99 | M7: PayPal | N7: Delivered
A8: ORD-1007 | B8: 45309 | C8: James Martinez | D8: james.m@email.com | E8: East | F8: Philadelphia | G8: Books | H8: Programming Guide | I8: 1 | J8: 54.99 | K8: 10 | L8: 3.99 | M8: Credit Card | N8: Cancelled
A9: ORD-1008 | B9: 45311 | C9: Patricia Taylor | D9: patricia.t@email.com | E9: West | F9: San Francisco | G9: Clothing | H9: Denim Jeans | I9: 2 | J9: 59.99 | K9: 15 | L9: 7.99 | M9: Credit Card | N9: Delivered
A10: ORD-1009 | B10: 45313 | C10: Robert Thomas | D10: robert.t@email.com | E10: North | F10: Detroit | G10: Electronics | H10: Webcam | I10: 1 | J10: 79.99 | K10: 0 | L10: 6.5 | M10: Debit Card | N10: Processing
A11: ORD-1010 | B11: 45316 | C11: Jennifer Lee | D11: jennifer.l@email.com | E11: South | F11: Atlanta | G11: Books | H11: Business Strategy | I11: 2 | J11: 39.99 | K11: 5 | L11: 4.5 | M11: PayPal | N11: Delivered
A12: ORD-1011 | B12: 45319 | C12: William White | D12: william.w@email.com | E12: East | F12: New York | G12: Electronics | H12: Laptop Stand | I12: 1 | J12: 49.99 | K12: 10 | L12: 8.5 | M12: Credit Card | N12: Delivered
A13: ORD-1012 | B13: 45323 | C13: Mary Harris | D13: mary.h@email.com | E13: West | F13: Seattle | G13: Home & Garden | H13: Decorative Vase | I13: 3 | J13: 24.99 | K13: 0 | L13: 5.99 | M13: PayPal | N13: Delivered
... A101: ORD-1100 | B101: 45545 | C101: Norma Jordan | D101: norma.j@email.com | E101: West | F101: Los Angeles | G101: Books | H101: Educational | I101: 2 | J101: 44.99 | K101: 10 | L101: 5.5 | M101: Credit Card | N101: Delivered

Sheet sales_data
A1: Order_ID | B1: Order_Date | C1: Month | D1: Customer_Name | E1: Customer_Email | F1: Region | G1: City | H1: Product_Category | I1: Product_Name | J1: Quantity | K1: Unit_Price | L1: Subtotal | M1: Discount_Percent | N1: Discount_Amount | O1: Net_Amount | P1: Shipping_Cost | Q1: Total Order Value | R1: Revenue Category | S1: Payment_Method | T1: Order_Status
A2: ORD-1037 | B2: 45385 | C2: =TEXT(SalesData[[#This Row],[Order_Date]],"MMMM") -> April | D2: Justin Edwards | E2: justin.e@email.com | F2: North | G2: Minneapolis | H2: Books | I2: Cookbook | J2: 1 | K2: 34.99 | L2: =SalesData[[#This Row],[Unit_Price]]*SalesData[[#This Row],[Quantity]] -> 34.99 | M2: 5 | N2: =SalesData[[#This Row],[Subtotal]]*(SalesData[[#This Row],[Discount_Percent]]/100) -> 1.7495 | O2: =SalesData[[#This Row],[Subtotal]]-SalesData[[#This Row],[Discount_Amount]] -> 33.2405 | P2: 3.99 | Q2: =SUM(SalesData[[#This Row],[Net_Amount]]+SalesData[[#This Row],[Shipping_Cost]]) -> 37.2305 | R2: =IF(SalesData[[#This Row],[Total Order Value]]>200,"High Value",IF(SalesData[[#This Row],[Total Order Value]]>100,"Medium Value","Low Value")) -> Low Value | S2: Debit Card | T2: Delivered
A3: ORD-1049 | B3: 45415 | C3: =TEXT(SalesData[[#This Row],[Order_Date]],"MMMM") -> May | D3: Gregory Cooper | E3: gregory.c@email.com | F3: North | G3: Minneapolis | H3: Clothing | I3: Track Pants | J3: 1 | K3: 44.99 | L3: =SalesData[[#This Row],[Unit_Price]]*SalesData[[#This Row],[Quantity]] -> 44.99 | M3: 25 | N3: =SalesData[[#This Row],[Subtotal]]*(SalesData[[#This Row],[Discount_Percent]]/100) -> 11.2475 | O3: =SalesData[[#This Row],[Subtotal]]-SalesData[[#This Row],[Discount_Amount]] -> 33.7425 | P3: 6.5 | Q3: =SUM(SalesData[[#This Row],[Net_Amount]]+SalesData[[#This Row],[Shipping_Cost]]) -> 40.2425 | R3: =IF(SalesData[[#This Row],[Total Order Value]]>200,"High Value",IF(SalesData[[#This Row],[Total Order Value]]>100,"Medium Value","Low Value")) -> Low Value | S3: PayPal | T3: Delivered
A4: ORD-1021 | B4: 45344 | C4: =TEXT(SalesData[[#This Row],[Order_Date]],"MMMM") -> February | D4: Joseph Lopez | E4: joseph.l@email.com | F4: North | G4: Detroit | H4: Home & Garden | I4: Wall Clock | J4: 1 | K4: 39.99 | L4: =SalesData[[#This Row],[Unit_Price]]*SalesData[[#This Row],[Quantity]] -> 39.99 | M4: 10 | N4: =SalesData[[#This Row],[Subtotal]]*(SalesData[[#This Row],[Discount_Percent]]/100) -> 3.999 | O4: =SalesData[[#This Row],[Subtotal]]-SalesData[[#This Row],[Discount_Amount]] -> 35.991 | P4: 5.99 | Q4: =SUM(SalesData[[#This Row],[Net_Amount]]+SalesData[[#This Row],[Shipping_Cost]]) -> 41.981 | R4: =IF(SalesData[[#This Row],[Total Order Value]]>200,"High Value",IF(SalesData[[#This Row],[Total Order Value]]>100,"Medium Value","Low Value")) -> Low Value | S4: Credit Card | T4: Delivered
A5: ORD-1069 | B5: 45465 | C5: =TEXT(SalesData[[#This Row],[Order_Date]],"MMMM") -> June | D5: Roger Coleman | E5: roger.c@email.com | F5: North | G5: Detroit | H5: Books | I5: Philosophy | J5: 1 | K5: 44.99 | L5: =SalesData[[#This Row],[Unit_Price]]*SalesData[[#This Row],[Quantity]] -> 44.99 | M5: 0 | N5: =SalesData[[#This Row],[Subtotal]]*(SalesData[[#This Row],[Discount_Percent]]/100) -> 0 | O5: =SalesData[[#This Row],[Subtotal]]-SalesData[[#This Row],[Discount_Amount]] -> 44.99 | P5: 4.5 | Q5: =SUM(SalesData[[#This Row],[Net_Amount]]+SalesData[[#This Row],[Shipping_Cost]]) -> 49.49 | R5: =IF(SalesData[[#This Row],[Total Order Value]]>200,"High Value",IF(SalesData[[#This Row],[Total Order Value]]>100,"Medium Value","Low Value")) -> Low Value | S5: Credit Card | T5: Delivered
A6: ORD-1073 | B6: 45476 | C6: =TEXT(SalesData[[#This Row],[Order_Date]],"MMMM") -> July | D6: Arthur Long | E6: arthur.l@email.com | F6: North | G6: Minneapolis | H6: Books | I6: Poetry | J6: 2 | K6: 24.99 | L6: =SalesData[[#This Row],[Unit_Price]]*SalesData[[#This Row],[Quantity]] -> 49.98 | M6: 0 | N6: =SalesData[[#This Row],[Subtotal]]*(SalesData[[#This Row],[Discount_Percent]]/100) -> 0 | O6: =SalesData[[#This Row],[Subtotal]]-SalesData[[#This Row],[Discount_Amount]] -> 49.98 | P6: 3.99 | Q6: =SUM(SalesData[[#This Row],[Net_Amount]]+SalesData[[#This Row],[Shipping_Cost]]) -> 53.97 | R6: =IF(SalesData[[#This Row],[Total Order Value]]>200,"High Value",IF(SalesData[[#This Row],[Total Order Value]]>100,"Medium Value","Low Value")) -> Low Value | S6: PayPal | T6: Delivered
A7: ORD-1033 | B7: 45373 | C7: =TEXT(SalesData[[#This Row],[Order_Date]],"MMMM") -> March | D7: Jason Phillips | E7: jason.p@email.com | F7: North | G7: Detroit | H7: Books | I7: History Book | J7: 1 | K7: 49.99 | L7: =SalesData[[#This Row],[Unit_Price]]*SalesData[[#This Row],[Quantity]] -> 49.99 | M7: 0 | N7: =SalesData[[#This Row],[Subtotal]]*(SalesData[[#This Row],[Discount_Percent]]/100) -> 0 | O7: =SalesData[[#This Row],[Subtotal]]-SalesData[[#This Row],[Discount_Amount]] -> 49.99 | P7: 4.99 | Q7: =SUM(SalesData[[#This Row],[Net_Amount]]+SalesData[[#This Row],[Shipping_Cost]]) -> 54.98 | R7: =IF(SalesData[[#This Row],[Total Order Value]]>200,"High Value",IF(SalesData[[#This Row],[Total Order Value]]>100,"Medium Value","Low Value")) -> Low Value | S7: Debit Card | T7: Delivered
A8: ORD-1081 | B8: 45495 | C8: =TEXT(SalesData[[#This Row],[Order_Date]],"MMMM") -> July | D8: Russell Gonzales | E8: russell.g@email.com | F8: North | G8: Detroit | H8: Clothing | I8: Gloves | J8: 4 | K8: 14.99 | L8: =SalesData[[#This Row],[Unit_Price]]*SalesData[[#This Row],[Quantity]] -> 59.96 | M8: 10 | N8: =SalesData[[#This Row],[Subtotal]]*(SalesData[[#This Row],[Discount_Percent]]/100) -> 5.996 | O8: =SalesData[[#This Row],[Subtotal]]-SalesData[[#This Row],[Discount_Amount]] -> 53.964 | P8: 4.5 | Q8: =SUM(SalesData[[#This Row],[Net_Amount]]+SalesData[[#This Row],[Shipping_Cost]]) -> 58.464 | R8: =IF(SalesData[[#This Row],[Total Order Value]]>200,"High Value",IF(SalesData[[#This Row],[Total Order Value]]>100,"Medium Value","Low Value")) -> Low Value | S8: Credit Card | T8: Delivered
A9: ORD-1001 | B9: 45296 | C9: =TEXT(SalesData[[#This Row],[Order_Date]],"MMMM") -> January | D9: John Smith | E9: john.smith@email.com | F9: North | G9: New York | H9: Electronics | I9: Wireless Mouse | J9: 2 | K9: 29.99 | L9: =SalesData[[#This Row],[Unit_Price]]*SalesData[[#This Row],[Quantity]] -> 59.98 | M9: 10 | N9: =SalesData[[#This Row],[Subtotal]]*(SalesData[[#This Row],[Discount_Percent]]/100) -> 5.998 | O9: =SalesData[[#This Row],[Subtotal]]-SalesData[[#This Row],[Discount_Amount]] -> 53.982 | P9: 5.99 | Q9: =SUM(SalesData[[#This Row],[Net_Amount]]+SalesData[[#This Row],[Shipping_Cost]]) -> 59.972 | R9: =IF(SalesData[[#This Row],[Total Order Value]]>200,"High Value",IF(SalesData[[#This Row],[Total Order Value]]>100,"Medium Value","Low Value")) -> Low Value | S9: Credit Card | T9: Delivered
A10: ORD-1061 | B10: 45446 | C10: =TEXT(SalesData[[#This Row],[Order_Date]],"MMMM") -> June | D10: Walter Kelly | E10: walter.k@email.com | F10: North | G10: Minneapolis | H10: Home & Garden | I10: Coat Rack | J10: 1 | K10: 69.99 | L10: =SalesData[[#This Row],[Unit_Price]]*SalesData[[#This Row],[Quantity]] -> 69.99 | M10: 15 | N10: =SalesData[[#This Row],[Subtotal]]*(SalesData[[#This Row],[Discount_Percent]]/100) -> 10.4985 | O10: =SalesData[[#This Row],[Subtotal]]-SalesData[[#This Row],[Discount_Amount]] -> 59.4915 | P10: 8.99 | Q10: =SUM(SalesData[[#This Row],[Net_Amount]]+SalesData[[#This Row],[Shipping_Cost]]) -> 68.4815 | R10: =IF(SalesData[[#This Row],[Total Order Value]]>200,"High Value",IF(SalesData[[#This Row],[Total Order Value]]>100,"Medium Value","Low Value")) -> Low Value | S10: Debit Card | T10: Delivered
A11: ORD-1053 | B11: 45424 | C11: =TEXT(SalesData[[#This Row],[Order_Date]],"MMMM") -> May | D11: Jonathan Ward | E11: jonathan.w@email.com | F11: North | G11: Chicago | H11: Electronics | I11: Screen Protector | J11: 5 | K11: 14.99 | L11: =SalesData[[#This Row],[Unit_Price]]*SalesData[[#This Row],[Quantity]] -> 74.95 | M11: 10 | N11: =SalesData[[#This Row],[Subtotal]]*(SalesData[[#This Row],[Discount_Percent]]/100) -> 7.495 | O11: =SalesData[[#This Row],[Subtotal]]-SalesData[[#This Row],[Discount_Amount]] -> 67.455 | P11: 2.99 | Q11: =SUM(SalesData[[#This Row],[Net_Amount]]+SalesData[[#This Row],[Shipping_Cost]]) -> 70.445 | R11: =IF(SalesData[[#This Row],[Total Order Value]]>200,"High Value",IF(SalesData[[#This Row],[Total Order Value]]>100,"Medium Value","Low Value")) -> Low Value | S11: Credit Card | T11: Processing | Y11: Regions | Z11: Order_Status
A12: ORD-1093 | B12: 45526 | C12: =TEXT(SalesData[[#This Row],[Order_Date]],"MMMM") -> August | D12: Henry Wallace | E12: henry.w@email.com | F12: North | G12: Detroit | H12: Home & Garden | I12: Key Holder | J12: 4 | K12: 17.99 | L12: =SalesData[[#This Row],[Unit_Price]]*SalesData[[#This Row],[Quantity]] -> 71.96 | M12: 5 | N12: =SalesData[[#This Row],[Subtotal]]*(SalesData[[#This Row],[Discount_Percent]]/100) -> 3.598 | O12: =SalesData[[#This Row],[Subtotal]]-SalesData[[#This Row],[Discount_Amount]] -> 68.362 | P12: 4.5 | Q12: =SUM(SalesData[[#This Row],[Net_Amount]]+SalesData[[#This Row],[Shipping_Cost]]) -> 72.862 | R12: =IF(SalesData[[#This Row],[Total Order Value]]>200,"High Value",IF(SalesData[[#This Row],[Total Order Value]]>100,"Medium Value","Low Value")) -> Low Value | S12: Debit Card | T12: Cancelled | Y12: North | Z12: Delivered
A13: ORD-1065 | B13: 45455 | C13: =TEXT(SalesData[[#This Row],[Order_Date]],"MMMM") -> June | D13: Gerald Wood | E13: gerald.w@email.com | F13: North | G13: Chicago | H13: Electronics | I13: Cable Organizer | J13: 6 | K13: 12.99 | L13: =SalesData[[#This Row],[Unit_Price]]*SalesData[[#This Row],[Quantity]] -> 77.94 | M13: 5 | N13: =SalesData[[#This Row],[Subtotal]]*(SalesData[[#This Row],[Discount_Percent]]/100) -> 3.897 | O13: =SalesData[[#This Row],[Subtotal]]-SalesData[[#This Row],[Discount_Amount]] -> 74.043 | P13: 2.99 | Q13: =SUM(SalesData[[#This Row],[Net_Amount]]+SalesData[[#This Row],[Shipping_Cost]]) -> 77.033 | R13: =IF(SalesData[[#This Row],[Total Order Value]]>200,"High Value",IF(SalesData[[#This Row],[Total Order Value]]>100,"Medium Value","Low Value")) -> Low Value | S13: Debit Card | T13: Cancelled | Y13: South | Z13: Processing
A14: ORD-1041 | B14: 45394 | C14: =TEXT(SalesData[[#This Row],[Order_Date]],"MMMM") -> April | D14: Eric Rogers | E14: eric.r@email.com | F14: North | G14: Chicago | H14: Electronics | I14: Power Bank | J14: 2 | K14: 44.99 | L14: =SalesData[[#This Row],[Unit_Price]]*SalesData[[#This Row],[Quantity]] -> 89.98 | M14: 15 | N14: =SalesData[[#This Row],[Subtotal]]*(SalesData[[#This Row],[Discount_Percent]]/100) -> 13.497 | O14: =SalesData[[#This Row],[Subtotal]]-SalesData[[#This Row],[Discount_Amount]] -> 76.483 | P14: 5.5 | Q14: =SUM(SalesData[[#This Row],[Net_Amount]]+SalesData[[#This Row],[Shipping_Cost]]) -> 81.983 | R14: =IF(SalesData[[#This Row],[Total Order Value]]>200,"High Value",IF(SalesData[[#This Row],[Total Order Value]]>100,"Medium Value","Low Value")) -> Low Value | S14: Credit Card | T14: Delivered | Y14: East | Z14: Cancelled
A15: ORD-1097 | B15: 45538 | C15: =TEXT(SalesData[[#This Row],[Order_Date]],"MMMM") -> September | D15: Joe Newman | E15: joe.n@email.com | F15: North | G15: Minneapolis | H15: Home & Garden | I15: Mirror | J15: 1 | K15: 89.99 | L15: =SalesData[[#This Row],[Unit_Price]]*SalesData[[#This Row],[Quantity]] -> 89.99 | M15: 20 | N15: =SalesData[[#This Row],[Subtotal]]*(SalesData[[#This Row],[Discount_Percent]]/100) -> 17.998 | O15: =SalesData[[#This Row],[Subtotal]]-SalesData[[#This Row],[Discount_Amount]] -> 71.992 | P15: 11.99 | Q15: =SUM(SalesData[[#This Row],[Net_Amount]]+SalesData[[#This Row],[Shipping_Cost]]) -> 83.982 | R15: =IF(SalesData[[#This Row],[Total Order Value]]>200,"High Value",IF(SalesData[[#This Row],[Total Order Value]]>100,"Medium Value","Low Value")) -> Low Value | S15: Credit Card | T15: Delivered | Y15: West
A16: ORD-1009 | B16: 45313 | C16: =TEXT(SalesData[[#This Row],[Order_Date]],"MMMM") -> January | D16: Robert Thomas | E16: robert.t@email.com | F16: North | G16: Detroit | H16: Electronics | I16: Webcam | J16: 1 | K16: 79.99 | L16: =SalesData[[#This Row],[Unit_Price]]*SalesData[[#This Row],[Quantity]] -> 79.99 | M16: 0 | N16: =SalesData[[#This Row],[Subtotal]]*(SalesData[[#This Row],[Discount_Percent]]/100) -> 0 | O16: =SalesData[[#This Row],[Subtotal]]-SalesData[[#This Row],[Discount_Amount]] -> 79.99 | P16: 6.5 | Q16: =SUM(SalesData[[#This Row],[Net_Amount]]+SalesData[[#This Row],[Shipping_Cost]]) -> 86.49 | R16: =IF(SalesData[[#This Row],[Total Order Value]]>200,"High Value",IF(SalesData[[#This Row],[Total Order Value]]>100,"Medium Value","Low Value")) -> Low Value | S16: Debit Card | T16: Processing
A17: ORD-1077 | B17: 45485 | C17: =TEXT(SalesData[[#This Row],[Order_Date]],"MMMM") -> July | D17: Louis Washington | E17: louis.w@email.com | F17: North | G17: Chicago | H17: Electronics | I17: Car Charger | J17: 5 | K17: 19.99 | L17: =SalesData[[#This Row],[Unit_Price]]*SalesData[[#This Row],[Quantity]] -> 99.95 | M17: 15 | N17: =SalesData[[#This Row],[Subtotal]]*(SalesData[[#This Row],[Discount_Percent]]/100) -> 14.9925 | O17: =SalesData[[#This Row],[Subtotal]]-SalesData[[#This Row],[Discount_Amount]] -> 84.9575 | P17: 3.99 | Q17: =SUM(SalesData[[#This Row],[Net_Amount]]+SalesData[[#This Row],[Shipping_Cost]]) -> 88.9475 | R17: =IF(SalesData[[#This Row],[Total Order Value]]>200,"High Value",IF(SalesData[[#This Row],[Total Order Value]]>100,"Medium Value","Low Value")) -> Low Value | S17: PayPal | T17: Delivered
A18: ORD-1057 | B18: 45434 | C18: =TEXT(SalesData[[#This Row],[Order_Date]],"MMMM") -> May | D18: Dennis Ramirez | E18: dennis.r@email.com | F18: North | G18: Detroit | H18: Home & Garden | I18: Floor Mat | J18: 3 | K18: 29.99 | L18: =SalesData[[#This Row],[Unit_Price]]*SalesData[[#This Row],[Quantity]] -> 89.97 | M18: 5 | N18: =SalesData[[#This Row],[Subtotal]]*(SalesData[[#This Row],[Discount_Percent]]/100) -> 4.4985 | O18: =SalesData[[#This Row],[Subtotal]]-SalesData[[#This Row],[Discount_Amount]] -> 85.4715 | P18: 5.99 | Q18: =SUM(SalesData[[#This Row],[Net_Amount]]+SalesData[[#This Row],[Shipping_Cost]]) -> 91.4615 | R18: =IF(SalesData[[#This Row],[Total Order Value]]>200,"High Value",IF(SalesData[[#This Row],[Total Order Value]]>100,"Medium Value","Low Value")) -> Low Value | S18: Credit Card | T18: Delivered
A19: ORD-1005 | B19: 45303 | C19: =TEXT(SalesData[[#This Row],[Order_Date]],"MMMM") -> January | D19: David Wilson | E19: d.wilson@email.com | F19: North | G19: Chicago | H19: Electronics | I19: Keyboard | J19: 1 | K19: 89.99 | L19: =SalesData[[#This Row],[Unit_Price]]*SalesData[[#This Row],[Quantity]] -> 89.99 | M19: 5 | N19: =SalesData[[#This Row],[Subtotal]]*(SalesData[[#This Row],[Discount_Percent]]/100) -> 4.4995 | O19: =SalesData[[#This Row],[Subtotal]]-SalesData[[#This Row],[Discount_Amount]] -> 85.4905 | P19: 8.99 | Q19: =SUM(SalesData[[#This Row],[Net_Amount]]+SalesData[[#This Row],[Shipping_Cost]]) -> 94.4805 | R19: =IF(SalesData[[#This Row],[Total Order Value]]>200,"High Value",IF(SalesData[[#This Row],[Total Order Value]]>100,"Medium Value","Low Value")) -> Low Value | S19: Credit Card | T19: Delivered
A20: ORD-1085 | B20: 45507 | C20: =TEXT(SalesData[[#This Row],[Order_Date]],"MMMM") -> August | D20: Randy Griffin | E20: randy.g@email.com | F20: North | G20: Minneapolis | H20: Clothing | I20: Socks Pack | J20: 6 | K20: 19.99 | L20: =SalesData[[#This Row],[Unit_Price]]*SalesData[[#This Row],[Quantity]] -> 119.94 | M20: 25 | N20: =SalesData[[#This Row],[Subtotal]]*(SalesData[[#This Row],[Discount_Percent]]/100) -> 29.985 | O20: =SalesData[[#This Row],[Subtotal]]-SalesData[[#This Row],[Discount_Amount]] -> 89.955 | P20: 4.99 | Q20: =SUM(SalesData[[#This Row],[Net_Amount]]+SalesData[[#This Row],[Shipping_Cost]]) -> 94.945 | R20: =IF(SalesData[[#This Row],[Total Order Value]]>200,"High Value",IF(SalesData[[#This Row],[Total Order Value]]>100,"Medium Value","Low Value")) -> Low Value | S20: Credit Card | T20: Delivered
A21: ORD-1045 | B21: 45404 | C21: =TEXT(SalesData[[#This Row],[Order_Date]],"MMMM") -> April | D21: Nicholas Bell | E21: nicholas.b@email.com | F21: North | G21: Detroit | H21: Clothing | I21: Sweatshirt | J21: 2 | K21: 54.99 | L21: =SalesData[[#This Row],[Unit_Price]]*SalesData[[#This Row],[Quantity]] -> 109.98 | M21: 20 | N21: =SalesData[[#This Row],[Subtotal]]*(SalesData[[#This Row],[Discount_Percent]]/100) -> 21.996 | O21: =SalesData[[#This Row],[Subtotal]]-SalesData[[#This Row],[Discount_Amount]] -> 87.984 | P21: 7.99 | Q21: =SUM(SalesData[[#This Row],[Net_Amount]]+SalesData[[#This Row],[Shipping_Cost]]) -> 95.974 | R21: =IF(SalesData[[#This Row],[Total Order Value]]>200,"High Value",IF(SalesData[[#This Row],[Total Order Value]]>100,"Medium Value","Low Value")) -> Low Value | S21: PayPal | T21: Processing
A22: ORD-1029 | B22: 45363 | C22: =TEXT(SalesData[[#This Row],[Order_Date]],"MMMM") -> March | D22: George Mitchell | E22: george.m@email.com | F22: North | G22: Chicago | H22: Electronics | I22: External Hard Drive | J22: 1 | K22: 119.99 | L22: =SalesData[[#This Row],[Unit_Price]]*SalesData[[#This Row],[Quantity]] -> 119.99 | M22: 15 | N22: =SalesData[[#This Row],[Subtotal]]*(SalesData[[#This Row],[Discount_Percent]]/100) -> 17.9985 | O22: =SalesData[[#This Row],[Subtotal]]-SalesData[[#This Row],[Discount_Amount]] -> 101.9915 | P22: 9.99 | Q22: =SUM(SalesData[[#This Row],[Net_Amount]]+SalesData[[#This Row],[Shipping_Cost]]) -> 111.9815 | R22: =IF(SalesData[[#This Row],[Total Order Value]]>200,"High Value",IF(SalesData[[#This Row],[Total Order Value]]>100,"Medium Value","Low Value")) -> Medium Value | S22: Credit Card | T22: Delivered
A23: ORD-1013 | B23: 45325 | C23: =TEXT(SalesData[[#This Row],[Order_Date]],"MMMM") -> February | D23: Christopher Clark | E23: chris.c@email.com | F23: North | G23: Minneapolis | H23: Clothing | I23: Winter Jacket | J23: 1 | K23: 129.99 | L23: =SalesData[[#This Row],[Unit_Price]]*SalesData[[#This Row],[Quantity]] -> 129.99 | M23: 20 | N23: =SalesData[[#This Row],[Subtotal]]*(SalesData[[#This Row],[Discount_Percent]]/100) -> 25.998 | O23: =SalesData[[#This Row],[Subtotal]]-SalesData[[#This Row],[Discount_Amount]] -> 103.992 | P23: 12.99 | Q23: =SUM(SalesData[[#This Row],[Net_Amount]]+SalesData[[#This Row],[Shipping_Cost]]) -> 116.982 | R23: =IF(SalesData[[#This Row],[Total Order Value]]>200,"High Value",IF(SalesData[[#This Row],[Total Order Value]]>100,"Medium Value","Low Value")) -> Medium Value | S23: Credit Card | T23: Delivered
A24: ORD-1025 | B24: 45354 | C24: =TEXT(SalesData[[#This Row],[Order_Date]],"MMMM") -> March | D24: Paul Adams | E24: paul.a@email.com | F24: North | G24: Minneapolis | H24: Home & Garden | I24: Cushion Set | J24: 2 | K24: 54.99 | L24: =SalesData[[#This Row],[Unit_Price]]*SalesData[[#This Row],[Quantity]] -> 109.98 | M24: 0 | N24: =SalesData[[#This Row],[Subtotal]]*(SalesData[[#This Row],[Discount_Percent]]/100) -> 0 | O24: =SalesData[[#This Row],[Subtotal]]-SalesData[[#This Row],[Discount_Amount]] -> 109.98 | P24: 8.5 | Q24: =SUM(SalesData[[#This Row],[Net_Amount]]+SalesData[[#This Row],[Shipping_Cost]]) -> 118.48 | R24: =IF(SalesData[[#This Row],[Total Order Value]]>200,"High Value",IF(SalesData[[#This Row],[Total Order Value]]>100,"Medium Value","Low Value")) -> Medium Value | S24: Credit Card | T24: Delivered
A25: ORD-1017 | B25: 45334 | C25: =TEXT(SalesData[[#This Row],[Order_Date]],"MMMM") -> February | D25: Matthew Allen | E25: matt.a@email.com | F25: North | G25: Chicago | H25: Electronics | I25: Monitor | J25: 1 | K25: 299.99 | L25: =SalesData[[#This Row],[Unit_Price]]*SalesData[[#This Row],[Quantity]] -> 299.99 | M25: 10 | N25: =SalesData[[#This Row],[Subtotal]]*(SalesData[[#This Row],[Discount_Percent]]/100) -> 29.999 | O25: =SalesData[[#This Row],[Subtotal]]-SalesData[[#This Row],[Discount_Amount]] -> 269.991 | P25: 15.99 | Q25: =SUM(SalesData[[#This Row],[Net_Amount]]+SalesData[[#This Row],[Shipping_Cost]]) -> 285.981 | R25: =IF(SalesData[[#This Row],[Total Order Value]]>200,"High Value",IF(SalesData[[#This Row],[Total Order Value]]>100,"Medium Value","Low Value")) -> High Value | S25: Credit Card | T25: Delivered
A26: ORD-1089 | B26: 45516 | C26: =TEXT(SalesData[[#This Row],[Order_Date]],"MMMM") -> August | D26: Jack Ford | E26: jack.f@email.com | F26: North | G26: Chicago | H26: Electronics | I26: VR Headset | J26: 1 | K26: 399.99 | L26: =SalesData[[#This Row],[Unit_Price]]*SalesData[[#This Row],[Quantity]] -> 399.99 | M26: 20 | N26: =SalesData[[#This Row],[Subtotal]]*(SalesData[[#This Row],[Discount_Percent]]/100) -> 79.998 | O26: =SalesData[[#This Row],[Subtotal]]-SalesData[[#This Row],[Discount_Amount]] -> 319.992 | P26: 19.99 | Q26: =SUM(SalesData[[#This Row],[Net_Amount]]+SalesData[[#This Row],[Shipping_Cost]]) -> 339.982 | R26: =IF(SalesData[[#This Row],[Total Order Value]]>200,"High Value",IF(SalesData[[#This Row],[Total Order Value]]>100,"Medium Value","Low Value")) -> High Value | S26: Debit Card | T26: Delivered
A27: ORD-1066 | B27: 45458 | C27: =TEXT(SalesData[[#This Row],[Order_Date]],"MMMM") -> June | D27: Judith Barnes | E27: judith.b@email.com | F27: South | G27: Miami | H27: Home & Garden | I27: Napkin Holder | J27: 2 | K27: 24.99 | L27: =SalesData[[#This Row],[Unit_Price]]*SalesData[[#This Row],[Quantity]] -> 49.98 | M27: 15 | N27: =SalesData[[#This Row],[Subtotal]]*(SalesData[[#This Row],[Discount_Percent]]/100) -> 7.497 | O27: =SalesData[[#This Row],[Subtotal]]-SalesData[[#This Row],[Discount_Amount]] -> 42.483 | P27: 5.5 | Q27: =SUM(SalesData[[#This Row],[Net_Amount]]+SalesData[[#This Row],[Shipping_Cost]]) -> 47.983 | R27: =IF(SalesData[[#This Row],[Total Order Value]]>200,"High Value",IF(SalesData[[#This Row],[Total Order Value]]>100,"Medium Value","Low Value")) -> Low Value | S27: PayPal | T27: Delivered
... A101: ORD-1092 | B101: 45524 | C101: =TEXT(SalesData[[#This Row],[Order_Date]],"MMMM") -> August | D101: Martha Sullivan | E101: martha.s@email.com | F101: West | G101: San Francisco | H101: Electronics | I101: Smart Doorbell | J101: 1 | K101: 179.99 | L101: =SalesData[[#This Row],[Unit_Price]]*SalesData[[#This Row],[Quantity]] -> 179.99 | M101: 15 | N101: =SalesData[[#This Row],[Subtotal]]*(SalesData[[#This Row],[Discount_Percent]]/100) -> 26.9985 | O101: =SalesData[[#This Row],[Subtotal]]-SalesData[[#This Row],[Discount_Amount]] -> 152.9915 | P101: 12.99 | Q101: =SUM(SalesData[[#This Row],[Net_Amount]]+SalesData[[#This Row],[Shipping_Cost]]) -> 165.9815 | R101: =IF(SalesData[[#This Row],[Total Order Value]]>200,"High Value",IF(SalesData[[#This Row],[Total Order Value]]>100,"Medium Value","Low Value")) -> Medium Value | S101: Credit Card | T101: Delivered

Sheet sorted_analysis
A1: Order_ID | B1: Order_Date | C1: Month | D1: Customer_Name | E1: Customer_Email | F1: Region | G1: City | H1: Product_Category | I1: Product_Name | J1: Quantity | K1: Unit_Price | L1: Subtotal | M1: Discount_Percent | N1: Discount_Amount | O1: Net_Amount | P1: Shipping_Cost | Q1: Total Order Value | R1: Revenue Category | S1: Payment_Method | T1: Order_Status
A2: ORD-1037 | B2: 45385 | C2: =TEXT(sorted_analysis!$B2,"MMMM") -> April | D2: Justin Edwards | E2: justin.e@email.com | F2: North | G2: Minneapolis | H2: Books | I2: Cookbook | J2: 1 | K2: 34.99 | L2: =sorted_analysis!$K2*sorted_analysis!$J2 -> 34.99 | M2: 5 | N2: =sorted_analysis!$L2*(sorted_analysis!$M2/100) -> 1.7495 | O2: =sorted_analysis!$L2-sorted_analysis!$N2 -> 33.2405 | P2: 3.99 | Q2: =SUM(sorted_analysis!$O2+sorted_analysis!$P2) -> 37.2305 | R2: =IF(sorted_analysis!$Q2>200,"High Value",IF(sorted_analysis!$Q2>100,"Medium Value","Low Value")) -> Low Value | S2: Debit Card | T2: Delivered
A3: ORD-1049 | B3: 45415 | C3: =TEXT(sorted_analysis!$B3,"MMMM") -> May | D3: Gregory Cooper | E3: gregory.c@email.com | F3: North | G3: Minneapolis | H3: Clothing | I3: Track Pants | J3: 1 | K3: 44.99 | L3: =sorted_analysis!$K3*sorted_analysis!$J3 -> 44.99 | M3: 25 | N3: =sorted_analysis!$L3*(sorted_analysis!$M3/100) -> 11.2475 | O3: =sorted_analysis!$L3-sorted_analysis!$N3 -> 33.7425 | P3: 6.5 | Q3: =SUM(sorted_analysis!$O3+sorted_analysis!$P3) -> 40.2425 | R3: =IF(sorted_analysis!$Q3>200,"High Value",IF(sorted_analysis!$Q3>100,"Medium Value","Low Value")) -> Low Value | S3: PayPal | T3: Delivered
A4: ORD-1021 | B4: 45344 | C4: =TEXT(sorted_analysis!$B4,"MMMM") -> February | D4: Joseph Lopez | E4: joseph.l@email.com | F4: North | G4: Detroit | H4: Home & Garden | I4: Wall Clock | J4: 1 | K4: 39.99 | L4: =sorted_analysis!$K4*sorted_analysis!$J4 -> 39.99 | M4: 10 | N4: =sorted_analysis!$L4*(sorted_analysis!$M4/100) -> 3.999 | O4: =sorted_analysis!$L4-sorted_analysis!$N4 -> 35.991 | P4: 5.99 | Q4: =SUM(sorted_analysis!$O4+sorted_analysis!$P4) -> 41.981 | R4: =IF(sorted_analysis!$Q4>200,"High Value",IF(sorted_analysis!$Q4>100,"Medium Value","Low Value")) -> Low Value | S4: Credit Card | T4: Delivered
A5: ORD-1069 | B5: 45465 | C5: =TEXT(sorted_analysis!$B5,"MMMM") -> June | D5: Roger Coleman | E5: roger.c@email.com | F5: North | G5: Detroit | H5: Books | I5: Philosophy | J5: 1 | K5: 44.99 | L5: =sorted_analysis!$K5*sorted_analysis!$J5 -> 44.99 | M5: 0 | N5: =sorted_analysis!$L5*(sorted_analysis!$M5/100) -> 0 | O5: =sorted_analysis!$L5-sorted_analysis!$N5 -> 44.99 | P5: 4.5 | Q5: =SUM(sorted_analysis!$O5+sorted_analysis!$P5) -> 49.49 | R5: =IF(sorted_analysis!$Q5>200,"High Value",IF(sorted_analysis!$Q5>100,"Medium Value","Low Value")) -> Low Value | S5: Credit Card | T5: Delivered
A6: ORD-1073 | B6: 45476 | C6: =TEXT(sorted_analysis!$B6,"MMMM") -> July | D6: Arthur Long | E6: arthur.l@email.com | F6: North | G6: Minneapolis | H6: Books | I6: Poetry | J6: 2 | K6: 24.99 | L6: =sorted_analysis!$K6*sorted_analysis!$J6 -> 49.98 | M6: 0 | N6: =sorted_analysis!$L6*(sorted_analysis!$M6/100) -> 0 | O6: =sorted_analysis!$L6-sorted_analysis!$N6 -> 49.98 | P6: 3.99 | Q6: =SUM(sorted_analysis!$O6+sorted_analysis!$P6) -> 53.97 | R6: =IF(sorted_analysis!$Q6>200,"High Value",IF(sorted_analysis!$Q6>100,"Medium Value","Low Value")) -> Low Value | S6: PayPal | T6: Delivered
A7: ORD-1033 | B7: 45373 | C7: =TEXT(sorted_analysis!$B7,"MMMM") -> March | D7: Jason Phillips | E7: jason.p@email.com | F7: North | G7: Detroit | H7: Books | I7: History Book | J7: 1 | K7: 49.99 | L7: =sorted_analysis!$K7*sorted_analysis!$J7 -> 49.99 | M7: 0 | N7: =sorted_analysis!$L7*(sorted_analysis!$M7/100) -> 0 | O7: =sorted_analysis!$L7-sorted_analysis!$N7 -> 49.99 | P7: 4.99 | Q7: =SUM(sorted_analysis!$O7+sorted_analysis!$P7) -> 54.98 | R7: =IF(sorted_analysis!$Q7>200,"High Value",IF(sorted_analysis!$Q7>100,"Medium Value","Low Value")) -> Low Value | S7: Debit Card | T7: Delivered
A8: ORD-1081 | B8: 45495 | C8: =TEXT(sorted_analysis!$B8,"MMMM") -> July | D8: Russell Gonzales | E8: russell.g@email.com | F8: North | G8: Detroit | H8: Clothing | I8: Gloves | J8: 4 | K8: 14.99 | L8: =sorted_analysis!$K8*sorted_analysis!$J8 -> 59.96 | M8: 10 | N8: =sorted_analysis!$L8*(sorted_analysis!$M8/100) -> 5.996 | O8: =sorted_analysis!$L8-sorted_analysis!$N8 -> 53.964 | P8: 4.5 | Q8: =SUM(sorted_analysis!$O8+sorted_analysis!$P8) -> 58.464 | R8: =IF(sorted_analysis!$Q8>200,"High Value",IF(sorted_analysis!$Q8>100,"Medium Value","Low Value")) -> Low Value | S8: Credit Card | T8: Delivered
A9: ORD-1001 | B9: 45296 | C9: =TEXT(sorted_analysis!$B9,"MMMM") -> January | D9: John Smith | E9: john.smith@email.com | F9: North | G9: New York | H9: Electronics | I9: Wireless Mouse | J9: 2 | K9: 29.99 | L9: =sorted_analysis!$K9*sorted_analysis!$J9 -> 59.98 | M9: 10 | N9: =sorted_analysis!$L9*(sorted_analysis!$M9/100) -> 5.998 | O9: =sorted_analysis!$L9-sorted_analysis!$N9 -> 53.982 | P9: 5.99 | Q9: =SUM(sorted_analysis!$O9+sorted_analysis!$P9) -> 59.972 | R9: =IF(sorted_analysis!$Q9>200,"High Value",IF(sorted_analysis!$Q9>100,"Medium Value","Low Value")) -> Low Value | S9: Credit Card | T9: Delivered
A10: ORD-1061 | B10: 45446 | C10: =TEXT(sorted_analysis!$B10,"MMMM") -> June | D10: Walter Kelly | E10: walter.k@email.com | F10: North | G10: Minneapolis | H10: Home & Garden | I10: Coat Rack | J10: 1 | K10: 69.99 | L10: =sorted_analysis!$K10*sorted_analysis!$J10 -> 69.99 | M10: 15 | N10: =sorted_analysis!$L10*(sorted_analysis!$M10/100) -> 10.4985 | O10: =sorted_analysis!$L10-sorted_analysis!$N10 -> 59.4915 | P10: 8.99 | Q10: =SUM(sorted_analysis!$O10+sorted_analysis!$P10) -> 68.4815 | R10: =IF(sorted_analysis!$Q10>200,"High Value",IF(sorted_analysis!$Q10>100,"Medium Value","Low Value")) -> Low Value | S10: Debit Card | T10: Delivered
A11: ORD-1053 | B11: 45424 | C11: =TEXT(sorted_analysis!$B11,"MMMM") -> May | D11: Jonathan Ward | E11: jonathan.w@email.com | F11: North | G11: Chicago | H11: Electronics | I11: Screen Protector | J11: 5 | K11: 14.99 | L11: =sorted_analysis!$K11*sorted_analysis!$J11 -> 74.95 | M11: 10 | N11: =sorted_analysis!$L11*(sorted_analysis!$M11/100) -> 7.495 | O11: =sorted_analysis!$L11-sorted_analysis!$N11 -> 67.455 | P11: 2.99 | Q11: =SUM(sorted_analysis!$O11+sorted_analysis!$P11) -> 70.445 | R11: =IF(sorted_analysis!$Q11>200,"High Value",IF(sorted_analysis!$Q11>100,"Medium Value","Low Value")) -> Low Value | S11: Credit Card | T11: Processing | Y11: Regions | Z11: Order_Status
A12: ORD-1093 | B12: 45526 | C12: =TEXT(sorted_analysis!$B12,"MMMM") -> August | D12: Henry Wallace | E12: henry.w@email.com | F12: North | G12: Detroit | H12: Home & Garden | I12: Key Holder | J12: 4 | K12: 17.99 | L12: =sorted_analysis!$K12*sorted_analysis!$J12 -> 71.96 | M12: 5 | N12: =sorted_analysis!$L12*(sorted_analysis!$M12/100) -> 3.598 | O12: =sorted_analysis!$L12-sorted_analysis!$N12 -> 68.362 | P12: 4.5 | Q12: =SUM(sorted_analysis!$O12+sorted_analysis!$P12) -> 72.862 | R12: =IF(sorted_analysis!$Q12>200,"High Value",IF(sorted_analysis!$Q12>100,"Medium Value","Low Value")) -> Low Value | S12: Debit Card | T12: Cancelled | Y12: North | Z12: Delivered
A13: ORD-1065 | B13: 45455 | C13: =TEXT(sorted_analysis!$B13,"MMMM") -> June | D13: Gerald Wood | E13: gerald.w@email.com | F13: North | G13: Chicago | H13: Electronics | I13: Cable Organizer | J13: 6 | K13: 12.99 | L13: =sorted_analysis!$K13*sorted_analysis!$J13 -> 77.94 | M13: 5 | N13: =sorted_analysis!$L13*(sorted_analysis!$M13/100) -> 3.897 | O13: =sorted_analysis!$L13-sorted_analysis!$N13 -> 74.043 | P13: 2.99 | Q13: =SUM(sorted_analysis!$O13+sorted_analysis!$P13) -> 77.033 | R13: =IF(sorted_analysis!$Q13>200,"High Value",IF(sorted_analysis!$Q13>100,"Medium Value","Low Value")) -> Low Value | S13: Debit Card | T13: Cancelled | Y13: South | Z13: Processing
A14: ORD-1041 | B14: 45394 | C14: =TEXT(sorted_analysis!$B14,"MMMM") -> April | D14: Eric Rogers | E14: eric.r@email.com | F14: North | G14: Chicago | H14: Electronics | I14: Power Bank | J14: 2 | K14: 44.99 | L14: =sorted_analysis!$K14*sorted_analysis!$J14 -> 89.98 | M14: 15 | N14: =sorted_analysis!$L14*(sorted_analysis!$M14/100) -> 13.497 | O14: =sorted_analysis!$L14-sorted_analysis!$N14 -> 76.483 | P14: 5.5 | Q14: =SUM(sorted_analysis!$O14+sorted_analysis!$P14) -> 81.983 | R14: =IF(sorted_analysis!$Q14>200,"High Value",IF(sorted_analysis!$Q14>100,"Medium Value","Low Value")) -> Low Value | S14: Credit Card | T14: Delivered | Y14: East | Z14: Cancelled
A15: ORD-1097 | B15: 45538 | C15: =TEXT(sorted_analysis!$B15,"MMMM") -> September | D15: Joe Newman | E15: joe.n@email.com | F15: North | G15: Minneapolis | H15: Home & Garden | I15: Mirror | J15: 1 | K15: 89.99 | L15: =sorted_analysis!$K15*sorted_analysis!$J15 -> 89.99 | M15: 20 | N15: =sorted_analysis!$L15*(sorted_analysis!$M15/100) -> 17.998 | O15: =sorted_analysis!$L15-sorted_analysis!$N15 -> 71.992 | P15: 11.99 | Q15: =SUM(sorted_analysis!$O15+sorted_analysis!$P15) -> 83.982 | R15: =IF(sorted_analysis!$Q15>200,"High Value",IF(sorted_analysis!$Q15>100,"Medium Value","Low Value")) -> Low Value | S15: Credit Card | T15: Delivered | Y15: West
A16: ORD-1009 | B16: 45313 | C16: =TEXT(sorted_analysis!$B16,"MMMM") -> January | D16: Robert Thomas | E16: robert.t@email.com | F16: North | G16: Detroit | H16: Electronics | I16: Webcam | J16: 1 | K16: 79.99 | L16: =sorted_analysis!$K16*sorted_analysis!$J16 -> 79.99 | M16: 0 | N16: =sorted_analysis!$L16*(sorted_analysis!$M16/100) -> 0 | O16: =sorted_analysis!$L16-sorted_analysis!$N16 -> 79.99 | P16: 6.5 | Q16: =SUM(sorted_analysis!$O16+sorted_analysis!$P16) -> 86.49 | R16: =IF(sorted_analysis!$Q16>200,"High Value",IF(sorted_analysis!$Q16>100,"Medium Value","Low Value")) -> Low Value | S16: Debit Card | T16: Processing
A17: ORD-1077 | B17: 45485 | C17: =TEXT(sorted_analysis!$B17,"MMMM") -> July | D17: Louis Washington | E17: louis.w@email.com | F17: North | G17: Chicago | H17: Electronics | I17: Car Charger | J17: 5 | K17: 19.99 | L17: =sorted_analysis!$K17*sorted_analysis!$J17 -> 99.95 | M17: 15 | N17: =sorted_analysis!$L17*(sorted_analysis!$M17/100) -> 14.9925 | O17: =sorted_analysis!$L17-sorted_analysis!$N17 -> 84.9575 | P17: 3.99 | Q17: =SUM(sorted_analysis!$O17+sorted_analysis!$P17) -> 88.9475 | R17: =IF(sorted_analysis!$Q17>200,"High Value",IF(sorted_analysis!$Q17>100,"Medium Value","Low Value")) -> Low Value | S17: PayPal | T17: Delivered
A18: ORD-1057 | B18: 45434 | C18: =TEXT(sorted_analysis!$B18,"MMMM") -> May | D18: Dennis Ramirez | E18: dennis.r@email.com | F18: North | G18: Detroit | H18: Home & Garden | I18: Floor Mat | J18: 3 | K18: 29.99 | L18: =sorted_analysis!$K18*sorted_analysis!$J18 -> 89.97 | M18: 5 | N18: =sorted_analysis!$L18*(sorted_analysis!$M18/100) -> 4.4985 | O18: =sorted_analysis!$L18-sorted_analysis!$N18 -> 85.4715 | P18: 5.99 | Q18: =SUM(sorted_analysis!$O18+sorted_analysis!$P18) -> 91.4615 | R18: =IF(sorted_analysis!$Q18>200,"High Value",IF(sorted_analysis!$Q18>100,"Medium Value","Low Value")) -> Low Value | S18: Credit Card | T18: Delivered
A19: ORD-1005 | B19: 45303 | C19: =TEXT(sorted_analysis!$B19,"MMMM") -> January | D19: David Wilson | E19: d.wilson@email.com | F19: North | G19: Chicago | H19: Electronics | I19: Keyboard | J19: 1 | K19: 89.99 | L19: =sorted_analysis!$K19*sorted_analysis!$J19 -> 89.99 | M19: 5 | N19: =sorted_analysis!$L19*(sorted_analysis!$M19/100) -> 4.4995 | O19: =sorted_analysis!$L19-sorted_analysis!$N19 -> 85.4905 | P19: 8.99 | Q19: =SUM(sorted_analysis!$O19+sorted_analysis!$P19) -> 94.4805 | R19: =IF(sorted_analysis!$Q19>200,"High Value",IF(sorted_analysis!$Q19>100,"Medium Value","Low Value")) -> Low Value | S19: Credit Card | T19: Delivered
A20: ORD-1085 | B20: 45507 | C20: =TEXT(sorted_analysis!$B20,"MMMM") -> August | D20: Randy Griffin | E20: randy.g@email.com | F20: North | G20: Minneapolis | H20: Clothing | I20: Socks Pack | J20: 6 | K20: 19.99 | L20: =sorted_analysis!$K20*sorted_analysis!$J20 -> 119.94 | M20: 25 | N20: =sorted_analysis!$L20*(sorted_analysis!$M20/100) -> 29.985 | O20: =sorted_analysis!$L20-sorted_analysis!$N20 -> 89.955 | P20: 4.99 | Q20: =SUM(sorted_analysis!$O20+sorted_analysis!$P20) -> 94.945 | R20: =IF(sorted_analysis!$Q20>200,"High Value",IF(sorted_analysis!$Q20>100,"Medium Value","Low Value")) -> Low Value | S20: Credit Card | T20: Delivered
A21: ORD-1045 | B21: 45404 | C21: =TEXT(sorted_analysis!$B21,"MMMM") -> April | D21: Nicholas Bell | E21: nicholas.b@email.com | F21: North | G21: Detroit | H21: Clothing | I21: Sweatshirt | J21: 2 | K21: 54.99 | L21: =sorted_analysis!$K21*sorted_analysis!$J21 -> 109.98 | M21: 20 | N21: =sorted_analysis!$L21*(sorted_analysis!$M21/100) -> 21.996 | O21: =sorted_analysis!$L21-sorted_analysis!$N21 -> 87.984 | P21: 7.99 | Q21: =SUM(sorted_analysis!$O21+sorted_analysis!$P21) -> 95.974 | R21: =IF(sorted_analysis!$Q21>200,"High Value",IF(sorted_analysis!$Q21>100,"Medium Value","Low Value")) -> Low Value | S21: PayPal | T21: Processing
A22: ORD-1029 | B22: 45363 | C22: =TEXT(sorted_analysis!$B22,"MMMM") -> March | D22: George Mitchell | E22: george.m@email.com | F22: North | G22: Chicago | H22: Electronics | I22: External Hard Drive | J22: 1 | K22: 119.99 | L22: =sorted_analysis!$K22*sorted_analysis!$J22 -> 119.99 | M22: 15 | N22: =sorted_analysis!$L22*(sorted_analysis!$M22/100) -> 17.9985 | O22: =sorted_analysis!$L22-sorted_analysis!$N22 -> 101.9915 | P22: 9.99 | Q22: =SUM(sorted_analysis!$O22+sorted_analysis!$P22) -> 111.9815 | R22: =IF(sorted_analysis!$Q22>200,"High Value",IF(sorted_analysis!$Q22>100,"Medium Value","Low Value")) -> Medium Value | S22: Credit Card | T22: Delivered
A23: ORD-1013 | B23: 45325 | C23: =TEXT(sorted_analysis!$B23,"MMMM") -> February | D23: Christopher Clark | E23: chris.c@email.com | F23: North | G23: Minneapolis | H23: Clothing | I23: Winter Jacket | J23: 1 | K23: 129.99 | L23: =sorted_analysis!$K23*sorted_analysis!$J23 -> 129.99 | M23: 20 | N23: =sorted_analysis!$L23*(sorted_analysis!$M23/100) -> 25.998 | O23: =sorted_analysis!$L23-sorted_analysis!$N23 -> 103.992 | P23: 12.99 | Q23: =SUM(sorted_analysis!$O23+sorted_analysis!$P23) -> 116.982 | R23: =IF(sorted_analysis!$Q23>200,"High Value",IF(sorted_analysis!$Q23>100,"Medium Value","Low Value")) -> Medium Value | S23: Credit Card | T23: Delivered
A24: ORD-1025 | B24: 45354 | C24: =TEXT(sorted_analysis!$B24,"MMMM") -> March | D24: Paul Adams | E24: paul.a@email.com | F24: North | G24: Minneapolis | H24: Home & Garden | I24: Cushion Set | J24: 2 | K24: 54.99 | L24: =sorted_analysis!$K24*sorted_analysis!$J24 -> 109.98 | M24: 0 | N24: =sorted_analysis!$L24*(sorted_analysis!$M24/100) -> 0 | O24: =sorted_analysis!$L24-sorted_analysis!$N24 -> 109.98 | P24: 8.5 | Q24: =SUM(sorted_analysis!$O24+sorted_analysis!$P24) -> 118.48 | R24: =IF(sorted_analysis!$Q24>200,"High Value",IF(sorted_analysis!$Q24>100,"Medium Value","Low Value")) -> Medium Value | S24: Credit Card | T24: Delivered
A25: ORD-1017 | B25: 45334 | C25: =TEXT(sorted_analysis!$B25,"MMMM") -> February | D25: Matthew Allen | E25: matt.a@email.com | F25: North | G25: Chicago | H25: Electronics | I25: Monitor | J25: 1 | K25: 299.99 | L25: =sorted_analysis!$K25*sorted_analysis!$J25 -> 299.99 | M25: 10 | N25: =sorted_analysis!$L25*(sorted_analysis!$M25/100) -> 29.999 | O25: =sorted_analysis!$L25-sorted_analysis!$N25 -> 269.991 | P25: 15.99 | Q25: =SUM(sorted_analysis!$O25+sorted_analysis!$P25) -> 285.981 | R25: =IF(sorted_analysis!$Q25>200,"High Value",IF(sorted_analysis!$Q25>100,"Medium Value","Low Value")) -> High Value | S25: Credit Card | T25: Delivered
A26: ORD-1089 | B26: 45516 | C26: =TEXT(sorted_analysis!$B26,"MMMM") -> August | D26: Jack Ford | E26: jack.f@email.com | F26: North | G26: Chicago | H26: Electronics | I26: VR Headset | J26: 1 | K26: 399.99 | L26: =sorted_analysis!$K26*sorted_analysis!$J26 -> 399.99 | M26: 20 | N26: =sorted_analysis!$L26*(sorted_analysis!$M26/100) -> 79.998 | O26: =sorted_analysis!$L26-sorted_analysis!$N26 -> 319.992 | P26: 19.99 | Q26: =SUM(sorted_analysis!$O26+sorted_analysis!$P26) -> 339.982 | R26: =IF(sorted_analysis!$Q26>200,"High Value",IF(sorted_analysis!$Q26>100,"Medium Value","Low Value")) -> High Value | S26: Debit Card | T26: Delivered
F27: North Count | Q27: =SUBTOTAL(3,Q2:Q26) -> 25
F28: North Total | Q28: =SUBTOTAL(9,Q2:Q26) -> 2376.8215
F29: North Average | Q29: =SUBTOTAL(1,Q2:Q26) -> 95.07286
A30: ORD-1066 | B30: 45458 | C30: =TEXT(sorted_analysis!$B30,"MMMM") -> June | D30: Judith Barnes | E30: judith.b@email.com | F30: South | G30: Miami | H30: Home & Garden | I30: Napkin Holder | J30: 2 | K30: 24.99 | L30: =sorted_analysis!$K30*sorted_analysis!$J30 -> 49.98 | M30: 15 | N30: =sorted_analysis!$L30*(sorted_analysis!$M30/100) -> 7.497 | O30: =sorted_analysis!$L30-sorted_analysis!$N30 -> 42.483 | P30: 5.5 | Q30: =SUM(sorted_analysis!$O30+sorted_analysis!$P30) -> 47.983 | R30: =IF(sorted_analysis!$Q30>200,"High Value",IF(sorted_analysis!$Q30>100,"Medium Value","Low Value")) -> Low Value | S30: PayPal | T30: Delivered
A31: ORD-1042 | B31: 45397 | C31: =TEXT(sorted_analysis!$B31,"MMMM") -> April | D31: Rebecca Reed | E31: rebecca.r@email.com | F31: South | G31: Atlanta | H31: Books | I31: Biography | J31: 1 | K31: 44.99 | L31: =sorted_analysis!$K31*sorted_analysis!$J31 -> 44.99 | M31: 0 | N31: =sorted_analysis!$L31*(sorted_analysis!$M31/100) -> 0 | O31: =sorted_analysis!$L31-sorted_analysis!$N31 -> 44.99 | P31: 4.5 | Q31: =SUM(sorted_analysis!$O31+sorted_analysis!$P31) -> 49.49 | R31: =IF(sorted_analysis!$Q31>200,"High Value",IF(sorted_analysis!$Q31>100,"Medium Value","Low Value")) -> Low Value | S31: PayPal | T31: Delivered
A32: ORD-1062 | B32: 45448 | C32: =TEXT(sorted_analysis!$B32,"MMMM") -> June | D32: Teresa Sanders | E32: teresa.s@email.com | F32: South | G32: Dallas | H32: Electronics | I32: Phone Holder | J32: 3 | K32: 19.99 | L32: =sorted_analysis!$K32*sorted_analysis!$J32 -> 59.97 | M32: 20 | N32: =sorted_analysis!$L32*(sorted_analysis!$M32/100) -> 11.994 | O32: =sorted_analysis!$L32-sorted_analysis!$N32 -> 47.976 | P32: 4.5 | Q32: =SUM(sorted_analysis!$O32+sorted_analysis!$P32) -> 52.476 | R32: =IF(sorted_analysis!$Q32>200,"High Value",IF(sorted_analysis!$Q32>100,"Medium Value","Low Value")) -> Low Value | S32: Credit Card | T32: Delivered
A33: ORD-1002 | B33: 45298 | C33: =TEXT(sorted_analysis!$B33,"MMMM") -> January | D33: Sarah Johnson | E33: sarah.j@email.com | F33: South | G33: Miami | H33: Home & Garden | I33: Plant Pot Set | J33: 1 | K33: 45.5 | L33: =sorted_analysis!$K33*sorted_analysis!$J33 -> 45.5 | M33: 0 | N33: =sorted_analysis!$L33*(sorted_analysis!$M33/100) -> 0 | O33: =sorted_analysis!$L33-sorted_analysis!$N33 -> 45.5 | P33: 7.5 | Q33: =SUM(sorted_analysis!$O33+sorted_analysis!$P33) -> 53 | R33: =IF(sorted_analysis!$Q33>200,"High Value",IF(sorted_analysis!$Q33>100,"Medium Value","Low Value")) -> Low Value | S33: PayPal | T33: Delivered
A34: ORD-1078 | B34: 45488 | C34: =TEXT(sorted_analysis!$B34,"MMMM") -> July | D34: Evelyn Butler | E34: evelyn.b@email.com | F34: South | G34: Dallas | H34: Books | I34: Memoir | J34: 1 | K34: 49.99 | L34: =sorted_analysis!$K34*sorted_analysis!$J34 -> 49.99 | M34: 0 | N34: =sorted_analysis!$L34*(sorted_analysis!$M34/100) -> 0 | O34: =sorted_analysis!$L34-sorted_analysis!$N34 -> 49.99 | P34: 4.99 | Q34: =SUM(sorted_analysis!$O34+sorted_analysis!$P34) -> 54.98 | R34: =IF(sorted_analysis!$Q34>200,"High Value",IF(sorted_analysis!$Q34>100,"Medium Value","Low Value")) -> Low Value | S34: Credit Card | T34: Delivered
A35: ORD-1046 | B35: 45407 | C35: =TEXT(sorted_analysis!$B35,"MMMM") -> April | D35: Deborah Murphy | E35: deborah.m@email.com | F35: South | G35: Dallas | H35: Books | I35: Travel Guide | J35: 2 | K35: 29.99 | L35: =sorted_analysis!$K35*sorted_analysis!$J35 -> 59.98 | M35: 15 | N35: =sorted_analysis!$L35*(sorted_analysis!$M35/100) -> 8.997 | O35: =sorted_analysis!$L35-sorted_analysis!$N35 -> 50.983 | P35: 4.99 | Q35: =SUM(sorted_analysis!$O35+sorted_analysis!$P35) -> 55.973 | R35: =IF(sorted_analysis!$Q35>200,"High Value",IF(sorted_analysis!$Q35>100,"Medium Value","Low Value")) -> Low Value | S35: Credit Card | T35: Delivered
A36: ORD-1074 | B36: 45478 | C36: =TEXT(sorted_analysis!$B36,"MMMM") -> July | D36: Frances Patterson | E36: frances.p@email.com | F36: South | G36: Atlanta | H36: Electronics | I36: Ring Light | J36: 1 | K36: 59.99 | L36: =sorted_analysis!$K36*sorted_analysis!$J36 -> 59.99 | M36: 20 | N36: =sorted_analysis!$L36*(sorted_analysis!$M36/100) -> 11.998 | O36: =sorted_analysis!$L36-sorted_analysis!$N36 -> 47.992 | P36: 7.99 | Q36: =SUM(sorted_analysis!$O36+sorted_analysis!$P36) -> 55.982 | R36: =IF(sorted_analysis!$Q36>200,"High Value",IF(sorted_analysis!$Q36>100,"Medium Value","Low Value")) -> Low Value | S36: Credit Card | T36: Processing
A37: ORD-1054 | B37: 45427 | C37: =TEXT(sorted_analysis!$B37,"MMMM") -> May | D37: Barbara Torres | E37: barbara.t@email.com | F37: South | G37: Houston | H37: Clothing | I37: Formal Shirt | J37: 1 | K37: 64.99 | L37: =sorted_analysis!$K37*sorted_analysis!$J37 -> 64.99 | M37: 20 | N37: =sorted_analysis!$L37*(sorted_analysis!$M37/100) -> 12.998 | O37: =sorted_analysis!$L37-sorted_analysis!$N37 -> 51.992 | P37: 7.99 | Q37: =SUM(sorted_analysis!$O37+sorted_analysis!$P37) -> 59.982 | R37: =IF(sorted_analysis!$Q37>200,"High Value",IF(sorted_analysis!$Q37>100,"Medium Value","Low Value")) -> Low Value | S37: Debit Card | T37: Delivered
A38: ORD-1082 | B38: 45498 | C38: =TEXT(sorted_analysis!$B38,"MMMM") -> July | D38: Cheryl Bryant | E38: cheryl.b@email.com | F38: South | G38: Miami | H38: Books | I38: Graphic Novel | J38: 2 | K38: 34.99 | L38: =sorted_analysis!$K38*sorted_analysis!$J38 -> 69.98 | M38: 15 | N38: =sorted_analysis!$L38*(sorted_analysis!$M38/100) -> 10.497 | O38: =sorted_analysis!$L38-sorted_analysis!$N38 -> 59.483 | P38: 4.5 | Q38: =SUM(sorted_analysis!$O38+sorted_analysis!$P38) -> 63.983 | R38: =IF(sorted_analysis!$Q38>200,"High Value",IF(sorted_analysis!$Q38>100,"Medium Value","Low Value")) -> Low Value | S38: Debit Card | T38: Processing
A39: ORD-1090 | B39: 45519 | C39: =TEXT(sorted_analysis!$B39,"MMMM") -> August | D39: Ann Hamilton | E39: ann.h@email.com | F39: South | G39: Atlanta | H39: Clothing | I39: Wallet | J39: 2 | K39: 34.99 | L39: =sorted_analysis!$K39*sorted_analysis!$J39 -> 69.98 | M39: 10 | N39: =sorted_analysis!$L39*(sorted_analysis!$M39/100) -> 6.998 | O39: =sorted_analysis!$L39-sorted_analysis!$N39 -> 62.982 | P39: 5.99 | Q39: =SUM(sorted_analysis!$O39+sorted_analysis!$P39) -> 68.972 | R39: =IF(sorted_analysis!$Q39>200,"High Value",IF(sorted_analysis!$Q39>100,"Medium Value","Low Value")) -> Low Value | S39: Credit Card | T39: Delivered
A40: ORD-1094 | B40: 45529 | C40: =TEXT(sorted_analysis!$B40,"MMMM") -> August | D40: Diana Woods | E40: diana.w@email.com | F40: South | G40: Dallas | H40: Clothing | I40: Sunglasses | J40: 2 | K40: 44.99 | L40: =sorted_analysis!$K40*sorted_analysis!$J40 -> 89.98 | M40: 25 | N40: =sorted_analysis!$L40*(sorted_analysis!$M40/100) -> 22.495 | O40: =sorted_analysis!$L40-sorted_analysis!$N40 -> 67.485 | P40: 6.5 | Q40: =SUM(sorted_analysis!$O40+sorted_analysis!$P40) -> 73.985 | R40: =IF(sorted_analysis!$Q40>200,"High Value",IF(sorted_analysis!$Q40>100,"Medium Value","Low Value")) -> Low Value | S40: PayPal | T40: Delivered
...

Sheet Region_Analysis
B3: Column Labels
B4: Cancelled | D4: Delivered | F4: Processing | H4: Total Sum of Total Order Value | I4: Total Count of Order_ID
A5: Row Labels | B5: Sum of Total Order Value | C5: Count of Order_ID | D5: Sum of Total Order Value | E5: Count of Order_ID | F5: Sum of Total Order Value | G5: Count of Order_ID
A6: North | B6: 149.895 | C6: 2 | D6: 1974.0175 | E6: 20 | F6: 252.909 | G6: 3 | H6: 2376.8215 | I6: 25
A7: South | B7: 121.4715 | C7: 1 | D7: 1806.537 | E7: 21 | F7: 196.1575 | G7: 3 | H7: 2124.166 | I7: 25
A8: East | B8: 185.943 | C8: 3 | D8: 1176.3565 | E8: 17 | F8: 899.848 | G8: 5 | H8: 2262.1475 | I8: 25
A9: West | B9: 53.939 | C9: 1 | D9: 1915.0005 | E9: 22 | F9: 223.445 | G9: 2 | H9: 2192.3845 | I9: 25
A10: Grand Total | B10: 511.2485 | C10: 7 | D10: 6871.9115 | E10: 80 | F10: 1572.3595 | G10: 13 | H10: 8955.5195 | I10: 100

Sheet Product_Analysis
A3: % of Column Total | B3: Column Labels
A4: Row Labels | B4: January | C4: February | D4: March | E4: April | F4: May | G4: June | H4: July | I4: August | J4: September | K4: Grand Total
A5: Books | B5: 0.17043251 | C5: 0.082633331 | D5: 0.17071946 | E5: 0.17709929 | F5: 0.11250532 | G5: 0.18846129 | H5: 0.20855415 | I5: 0.046970993 | J5: 0.25414614 | K5: 0.13941843
A6: Clothing | B6: 0.20921945 | C6: 0.21037523 | D6: 0.14168786 | E6: 0.30957546 | F6: 0.17352516 | G6: 0.1662791 | H6: 0.18503629 | I6: 0.14240466 | J6: 0.22316368 | K6: 0.18845903
A7: Electronics | B7: 0.45117759 | C7: 0.50397341 | D7: 0.38772837 | E7: 0.32196305 | F7: 0.40492037 | G7: 0.35423972 | H7: 0.44608264 | I7: 0.64852265 | J7: 0.38175371 | K7: 0.45652589
A8: Home & Garden | B8: 0.16917045 | C8: 0.20301803 | D8: 0.29986431 | E8: 0.1913622 | F8: 0.30904915 | G8: 0.29101989 | H8: 0.16032692 | I8: 0.16210171 | J8: 0.14093647 | K8: 0.21559665
A9: Grand Total | B9: 1 | C9: 1 | D9: 1 | E9: 1 | F9: 1 | G9: 1 | H9: 1 | I9: 1 | J9: 1 | K9: 1

Sheet Customer_Analysis
B3: Column Labels
B4: Cancelled | D4: Delivered | F4: Processing | H4: Total Count of Customer_Name | I4: Total Sum of Total Order Value
A5: Row Labels | B5: Count of Customer_Name | C5: Sum of Total Order Value | D5: Count of Customer_Name | E5: Sum of Total Order Value | F5: Count of Customer_Name | G5: Sum of Total Order Value
A6: High Value | D6: 3 | E6: 853.4445 | F6: 1 | G6: 474.981 | H6: 4 | I6: 1328.4255
A7: North | D7: 2 | E7: 625.963 | H7: 2 | I7: 625.963
A8: South | D8: 1 | E8: 227.4815 | H8: 1 | I8: 227.4815
A9: East | F9: 1 | G9: 474.981 | H9: 1 | I9: 474.981
A10: Low Value | B10: 6 | C10: 389.777 | D10: 60 | E10: 3899.8715 | F10: 10 | G10: 775.935 | H10: 76 | I10: 5065.5835
A11: North | B11: 2 | C11: 149.895 | D11: 15 | E11: 1000.611 | F11: 3 | G11: 252.909 | H11: 20 | I11: 1403.415
A12: South | D12: 16 | E12: 1087.6575 | F12: 3 | G12: 196.1575 | H12: 19 | I12: 1283.815
A13: East | B13: 3 | C13: 185.943 | D13: 14 | E13: 825.4405 | F13: 3 | G13: 243.8855 | H13: 20 | I13: 1255.269
A14: West | B14: 1 | C14: 53.939 | D14: 15 | E14: 986.1625 | F14: 1 | G14: 82.983 | H14: 17 | I14: 1123.0845
A15: Medium Value | B15: 1 | C15: 121.4715 | D15: 17 | E15: 2118.5955 | F15: 2 | G15: 321.4435 | H15: 20 | I15: 2561.5105
A16: North | D16: 3 | E16: 347.4435 | H16: 3 | I16: 347.4435
A17: South | B17: 1 | C17: 121.4715 | D17: 4 | E17: 491.398 | H17: 5 | I17: 612.8695
A18: East | D18: 3 | E18: 350.916 | F18: 1 | G18: 180.9815 | H18: 4 | I18: 531.8975
A19: West | D19: 7 | E19: 928.838 | F19: 1 | G19: 140.462 | H19: 8 | I19: 1069.3
A20: Grand Total | B20: 7 | C20: 511.2485 | D20: 80 | E20: 6871.9115 | F20: 13 | G20: 1572.3595 | H20: 100 | I20: 8955.5195

Sheet Product_Trends
A1: Product Trends | B1: January | C1: February | D1: March | E1: April | F1: May | G1: June | H1: July | I1: August | J1: September | K1: Total | L1: Trend
A2: Electronics | B2: =COUNTIFS(sales_data!$H:$H,"Electronics",sales_data!$C:$C,"January") -> 5 | C2: =COUNTIFS(sales_data!$H:$H,"Electronics",sales_data!$C:$C,"February") -> 4 | D2: =COUNTIFS(sales_data!$H:$H,"Electronics",sales_data!$C:$C,"March") -> 4 | E2: =COUNTIFS(sales_data!$H:$H,"Electronics",sales_data!$C:$C,"April") -> 4 | F2: =COUNTIFS(sales_data!$H:$H,"Electronics",sales_data!$C:$C,"May") -> 4 | G2: =COUNTIFS(sales_data!$H:$H,"Electronics",sales_data!$C:$C,"June") -> 4 | H2: =COUNTIFS(sales_data!$H:$H,"Electronics",sales_data!$C:$C,"July") -> 4 | I2: =COUNTIFS(sales_data!$H:$H,"Electronics",sales_data!$C:$C,"August") -> 4 | J2: =COUNTIFS(sales_data!$H:$H,"Electronics",sales_data!$C:$C,"September") -> 1 | K2: =SUM(B2:J2) -> 34
A3: Home & Garden | B3: =COUNTIFS(sales_data!$H:$H,"Home & Garden",sales_data!$C:$C,"January") -> 2 | C3: =COUNTIFS(sales_data!$H:$H,"Home & Garden",sales_data!$C:$C,"February") -> 3 | D3: =COUNTIFS(sales_data!$H:$H,"Home & Garden",sales_data!$C:$C,"March") -> 3 | E3: =COUNTIFS(sales_data!$H:$H,"Home & Garden",sales_data!$C:$C,"April") -> 2 | F3: =COUNTIFS(sales_data!$H:$H,"Home & Garden",sales_data!$C:$C,"May") -> 3 | G3: =COUNTIFS(sales_data!$H:$H,"Home & Garden",sales_data!$C:$C,"June") -> 3 | H3: =COUNTIFS(sales_data!$H:$H,"Home & Garden",sales_data!$C:$C,"July") -> 2 | I3: =COUNTIFS(sales_data!$H:$H,"Home & Garden",sales_data!$C:$C,"August") -> 3 | J3: =COUNTIFS(sales_data!$H:$H,"Home & Garden",sales_data!$C:$C,"September") -> 1 | K3: =SUM(B3:J3) -> 22
A4: Clothing | B4: =COUNTIFS(sales_data!$H:$H,"Clothing",sales_data!$C:$C,"January") -> 2 | C4: =COUNTIFS(sales_data!$H:$H,"Clothing",sales_data!$C:$C,"February") -> 3 | D4: =COUNTIFS(sales_data!$H:$H,"Clothing",sales_data!$C:$C,"March") -> 2 | E4: =COUNTIFS(sales_data!$H:$H,"Clothing",sales_data!$C:$C,"April") -> 3 | F4: =COUNTIFS(sales_data!$H:$H,"Clothing",sales_data!$C:$C,"May") -> 3 | G4: =COUNTIFS(sales_data!$H:$H,"Clothing",sales_data!$C:$C,"June") -> 2 | H4: =COUNTIFS(sales_data!$H:$H,"Clothing",sales_data!$C:$C,"July") -> 3 | I4: =COUNTIFS(sales_data!$H:$H,"Clothing",sales_data!$C:$C,"August") -> 3 | J4: =COUNTIFS(sales_data!$H:$H,"Clothing",sales_data!$C:$C,"September") -> 1 | K4: =SUM(B4:J4) -> 22
A5: Books | B5: =COUNTIFS(sales_data!$H:$H,"Books",sales_data!$C:$C,"January") -> 2 | C5: =COUNTIFS(sales_data!$H:$H,"Books",sales_data!$C:$C,"February") -> 2 | D5: =COUNTIFS(sales_data!$H:$H,"Books",sales_data!$C:$C,"March") -> 3 | E5: =COUNTIFS(sales_data!$H:$H,"Books",sales_data!$C:$C,"April") -> 3 | F5: =COUNTIFS(sales_data!$H:$H,"Books",sales_data!$C:$C,"May") -> 2 | G5: =COUNTIFS(sales_data!$H:$H,"Books",sales_data!$C:$C,"June") -> 3 | H5: =COUNTIFS(sales_data!$H:$H,"Books",sales_data!$C:$C,"July") -> 3 | I5: =COUNTIFS(sales_data!$H:$H,"Books",sales_data!$C:$C,"August") -> 2 | J5: =COUNTIFS(sales_data!$H:$H,"Books",sales_data!$C:$C,"September") -> 2 | K5: =SUM(B5:J5) -> 22
